Workbook

Sheet List1
A1: Sklad | B1: Lokace | C1: Produkt | D1: Množstvo na lokácií | E1: Skladom | F1: Objem produktu | G1: Objem v M3 | H1: Celkový objem | I1: Predajnosť
A2: 162 SKLC3 | B2: 3E-22-11-4 | C2: BEU100d | D2: 10 | E2: 132 | F2: 18000 | G2: =F2/1000000 -> 0.018 | H2: =G2*D2 -> 0.18 | I2: =VLOOKUP(C2,Hárok1!F:G,2,0) -> 11
A3: 162 SKLC3 | B3: 3E-22-12-4 | C3: BEU100d | D3: 20 | E3: 132 | F3: 18000 | G3: =F3/1000000 -> 0.018 | H3: =G3*D3 -> 0.36 | I3: =VLOOKUP(C3,Hárok1!F:G,2,0) -> 11
A4: 162 SKLC3 | B4: 3E-22-13-1 | C4: BEU100d | D4: 12 | E4: 132 | F4: 18000 | G4: =F4/1000000 -> 0.018 | H4: =G4*D4 -> 0.216 | I4: =VLOOKUP(C4,Hárok1!F:G,2,0) -> 11
A5: 162 SKLC3 | B5: 3E-22-15-1 | C5: BEU100d | D5: 6 | E5: 132 | F5: 18000 | G5: =F5/1000000 -> 0.018 | H5: =G5*D5 -> 0.108 | I5: =VLOOKUP(C5,Hárok1!F:G,2,0) -> 11
A6: 162 SKLC3 | B6: 3G-06-26-2 | C6: BEU100d | D6: 7 | E6: 132 | F6: 18000 | G6: =F6/1000000 -> 0.018 | H6: =G6*D6 -> 0.126 | I6: =VLOOKUP(C6,Hárok1!F:G,2,0) -> 11
A7: 162 SKLC3 | B7: 3G-06-18-3 | C7: BEU100d | D7: 5 | E7: 132 | F7: 18000 | G7: =F7/1000000 -> 0.018 | H7: =G7*D7 -> 0.09 | I7: =VLOOKUP(C7,Hárok1!F:G,2,0) -> 11
A8: 162 SKLC3 | B8: 3F-16-8-1 | C8: BEU100d | D8: 6 | E8: 132 | F8: 18000 | G8: =F8/1000000 -> 0.018 | H8: =G8*D8 -> 0.108 | I8: =VLOOKUP(C8,Hárok1!F:G,2,0) -> 11
A9: 162 SKLC3 | B9: 3F-16-10-4 | C9: BEU100d | D9: 5 | E9: 132 | F9: 18000 | G9: =F9/1000000 -> 0.018 | H9: =G9*D9 -> 0.09 | I9: =VLOOKUP(C9,Hárok1!F:G,2,0) -> 11
A10: 162 SKLC3 | B10: 3F-17-10-3 | C10: BEU100d | D10: 5 | E10: 132 | F10: 18000 | G10: =F10/1000000 -> 0.018 | H10: =G10*D10 -> 0.09 | I10: =VLOOKUP(C10,Hárok1!F:G,2,0) -> 11
A11: 162 SKLC3 | B11: 3F-16-12-3 | C11: BEU100d | D11: 5 | E11: 132 | F11: 18000 | G11: =F11/1000000 -> 0.018 | H11: =G11*D11 -> 0.09 | I11: =VLOOKUP(C11,Hárok1!F:G,2,0) -> 11
A12: 162 SKLC3 | B12: 3F-16-14-2 | C12: BEU100d | D12: 2 | E12: 132 | F12: 18000 | G12: =F12/1000000 -> 0.018 | H12: =G12*D12 -> 0.036 | I12: =VLOOKUP(C12,Hárok1!F:G,2,0) -> 11
A13: 162 SKLC3 | B13: 3F-17-17-3 | C13: BEU100d | D13: 4 | E13: 132 | F13: 18000 | G13: =F13/1000000 -> 0.018 | H13: =G13*D13 -> 0.072 | I13: =VLOOKUP(C13,Hárok1!F:G,2,0) -> 11
... A32664: 162 SKLC3 | B32664: 3F-01-14-2 | C32664: TEFSN247 | D32664: 2 | E32664: 667 | F32664: 55343.75 | G32664: =F32664/1000000 -> 0.05534375 | H32664: =G32664*D32664 -> 0.1106875 | I32664: =VLOOKUP(C32664,Hárok1!F:G,2,0) -> 91
A32665: 162 SKLC3 | B32665: 3F-01-19-2 | C32665: TEFSN247 | D32665: 3 | E32665: 667 | F32665: 55343.75
A32666: 162 SKLC3 | B32666: 3F-01-21-1 | C32666: TEFSN247 | D32666: 3 | E32666: 667 | F32666: 55343.75
A32667: 162 SKLC3 | B32667: 3F-01-2-2 | C32667: TEFSN247 | D32667: 3 | E32667: 667 | F32667: 55343.75
A32668: 162 SKLC3 | B32668: 3F-01-2-3 | C32668: TEFSN247 | D32668: 2 | E32668: 667 | F32668: 55343.75
A32669: 162 SKLC3 | B32669: 3F-23-11-2 | C32669: TEFSN247 | D32669: 2 | E32669: 667 | F32669: 55343.75
A32670: 162 SKLC3 | B32670: 3F-23-14-4 | C32670: TEFSN247 | D32670: 5 | E32670: 667 | F32670: 55343.75
A32671: 162 SKLC3 | B32671: 3F-23-7-2 | C32671: TEFSN247 | D32671: 1 | E32671: 667 | F32671: 55343.75
A32672: 162 SKLC3 | B32672: 3H-08-10-4 | C32672: TEFSN247 | D32672: 7 | E32672: 667 | F32672: 55343.75
A32673: 162 SKLC3 | B32673: 3H-08-9-4 | C32673: TEFSN247 | D32673: 7 | E32673: 667 | F32673: 55343.75
A32674: 162 SKLC3 | B32674: 3H-09-10-4 | C32674: TEFSN247 | D32674: 5 | E32674: 667 | F32674: 55343.75
A32675: 162 SKLC3 | B32675: 3F-02-3-4 | C32675: TEFSN247 | D32675: 4 | E32675: 667 | F32675: 55343.75
A32676: 162 SKLC3 | B32676: 3F-02-5-4 | C32676: TEFSN247 | D32676: 4 | E32676: 667 | F32676: 55343.75
... A33951: 162 SKLC3 | B33951: 2SW-01-80-1 | C33951: YeeLa46 | D33951: 8 | E33951: 140 | F33951: 37740.672

Sheet Hárok1
F1: Produkt | G1: Predaje mesiac
A2: BEU100d | F2: BEU100d | G2: 11
A3: JL081a | F3: DY307i7 | G3: 103
A4: ECO101c | F4: EAN3001c2 | G4: 4556
A5: PB399b | F5: EAV8107 | G5: 19
A6: EAN3364f1 | F6: JL081a | G6: 24
A7: EAN3364f3 | F7: KPFC903 | G7: 1
A8: EAN3345a1 | F8: PB809i | G8: 2
A9: EAN3345a2 | F9: ECO101c | G9: 172
A10: PX600q1 | F10: BOC704b | G10: 1358
A11: PX600q1b | F11: PC185x5 | G11: 27
A12: FBT6400f | F12: EAN3364f1 | G12: 46
A13: EAV4271p | F13: EAN3364f3 | G13: 18
... A41: PRU003 | F41: TOPA018 | G41: 198
A42: AEY0961 | F42: SKLAD191d
A43: AEY0944 | F43: SPT2528 | G43: 11
A44: ETASV632 | F44: SPT2529 | G44: 10
A45: SINSP120 | F45: HRAa5593 | G45: 64
A46: CHPrk2772 | F46: HRAa5594 | G46: 13
A47: CHPrk2775 | F47: AUPR1433
A48: CHPrk2776 | F48: ZUB174 | G48: 1166
A49: CHPrk2988 | F49: EAD1326k | G49: 827
A50: KRMrk1356 | F50: DOMVPOP1 | G50: 30
A51: KRMrk1357 | F51: EAN2151b | G51: 119
A52: CHPrk3695 | F52: CIS068 | G52: 546
A53: PA497b2 | F53: CIS069 | G53: 651
A54: TEFRK951 | F54: IR303aF | G54: 150
A55: GORSP390 | F55: JT903c3 | G55: 41
A56: PRU008 | F56: EAV301a09 | G56: 105
A57: TEFSP245 | F57: KACZ025j2 | G57: 456
A58: TEFSN057 | F58: UKL043 | G58: 278
A59: TEFSN125 | F59: EAT2070f | G59: 56
... A205: TEFtlk30 | F205: SENSO468 | G205: 82
A206: HRAls6683 | F206: XXQR2
A207: PHIAK463HU | F207: ETABV595 | G207: 73
A208: LO31212 | F208: CHPrk4526 | G208: 452
A209: CONso92 | F209: CONKO146 | G209: 16
A210: DFLdrx70mb | F210: SENZH733 | G210: 37
A211: PC293a05t | F211: KRMrk1830 | G211: 295
A212: PE124a23j1 | F212: Kgso010 | G212: 42
...
